Workbook
Name Slicer_City: #N/A
Name Slicer_Payment_Mode: #N/A

Sheet Raw Dataset
A1: Order_ID | B1: Order_Time | C1: City | D1: Restaurant | E1: Order_Value | F1: Delivery_Fee | G1: Discount | H1: Payment_Mode | I1: Delivery_Time_Min | J1: Final_Amount
A2: ORD100000 | B2: 44927 | C2: Kolkata | D2: Pizza Corner | E2: 1349.85 | F2: 21.28 | G2: 462.51 | H2: Card | I2: 45 | J2: 908.6199999999999
A3: ORD100001 | B3: 44927.042 | C3: Hyderabad | D3: South Express | E3: 528.88 | F3: 64.92 | G3: 233.45 | H3: Card | I3: 82 | J3: 360.34999999999997
A4: ORD100002 | B4: 44927.083 | C4: Chennai | D4: Pizza Corner | E4: 1590.35 | F4: 93.1 | G4: 326.73 | H4: Wallet | I4: 15 | J4: 1356.7199999999998
A5: ORD100003 | B5: 44927.125 | C5: Delhi | D5: South Express | E5: 1834.73 | F5: 72.82 | G5: 92.2 | H5: Card | I5: 57 | J5: 1815.35
A6: ORD100004 | B6: 44927.167 | C6: Mumbai | D6: Urban Tadka | E6: 1374.42 | F6: 50.05 | G6: 394.49 | H6: Cash | I6: 55 | J6: 1029.98
A7: ORD100005 | B7: 44927.208 | C7: Hyderabad | D7: Tandoori Nights | E7: 1935.57 | F7: 5.7 | G7: 365.14 | H7: Wallet | I7: 28 | J7: 1576.13
A8: ORD100006 | B8: 44927.25 | C8: Kolkata | D8: Tandoori Nights | E8: 944.53 | F8: 0.76 | G8: 372.22 | H8: UPI | I8: 85 | J8: 573.0699999999999
A9: ORD100007 | B9: 44927.292 | C9: Delhi | D9: Spice Hub | E9: 1208.05 | F9: 97.27 | G9: 137.99 | H9: UPI | I9: 48 | J9: 1167.33
A10: ORD100008 | B10: 44927.333 | C10: Delhi | D10: Urban Tadka | E10: 572.48 | F10: 23.16 | G10: 177.53 | H10: UPI | I10: 76 | J10: 418.11
A11: ORD100009 | B11: 44927.375 | C11: Mumbai | D11: Pizza Corner | E11: 551.64 | F11: 54.33 | G11: 308.42 | H11: UPI | I11: 13 | J11: 297.55
A12: ORD100010 | B12: 44927.417 | C12: Chennai | D12: South Express | E12: 483.8 | F12: 64.17 | G12: 352.64 | H12: Card | I12: 72 | J12: 195.33000000000004
A13: ORD100011 | B13: 44927.458 | C13: Kolkata | D13: Biryani House | E13: 1838.77 | F13: 21.35 | G13: 198.95 | H13: Cash | I13: 10 | J13: 1661.1699999999998
A14: ORD100012 | B14: 44927.5 | C14: Chennai | D14: Pizza Corner | E14: 886.72 | F14: 12.85 | G14: 26.19 | H14: Cash | I14: 82 | J14: 873.38
A15: ORD100013 | B15: 44927.542 | C15: Pune | D15: Urban Tadka | E15: 1043.69 | F15: 79.71 | G15: 356.89 | H15: Card | I15: 58 | J15: 766.5100000000001
A16: ORD100014 | B16: 44927.583 | C16: Mumbai | D16: Tandoori Nights | E16: 1920.18 | F16: 11.99 | G16: 68.19 | H16: UPI | I16: 45 | J16: 1863.98
A17: ORD100015 | B17: 44927.625 | D17: Biryani House | E17: 404.41 | F17: 32.97 | G17: 118.16 | H17: UPI | I17: 79 | J17: 319.22
A18: ORD100016 | B18: 44927.667 | C18: Chennai | D18: Pizza Corner | E18: 895.09 | F18: 21.67 | G18: 412.06 | H18: Wallet | I18: 10 | J18: 504.7
A19: ORD100017 | B19: 44927.708 | C19: Pune | D19: Tandoori Nights | E19: 1861.77 | F19: 12.5 | G19: 29.64 | H19: Cash | I19: 73 | J19: 1844.6299999999999
A20: ORD100018 | B20: 44927.75 | C20: Kolkata | D20: Spice Hub | E20: 1183.04 | F20: 71.24 | G20: 239.14 | H20: UPI | I20: 52 | J20: 1015.14
A21: ORD100019 | B21: 44927.792 | C21: Bangalore | D21: Urban Tadka | E21: 827.72 | F21: 73.55 | G21: 59.43 | H21: Cash | I21: 38 | J21: 841.84
A22: ORD100020 | B22: 44927.833 | C22: Chennai | D22: Tandoori Nights | E22: 1091.84 | F22: 82.62 | G22: 188.33 | H22: UPI | I22: 27 | J22: 986.13
A23: ORD100021 | B23: 44927.875 | C23: Hyderabad | D23: South Express | E23: 1972.65 | F23: 73.61 | G23: 335.02 | H23: UPI | I23: 40 | J23: 1711.24
A24: ORD100022 | B24: 44927.917 | C24: Chennai | D24: South Express | E24: 650.05 | F24: 85.15 | G24: 307.57 | H24: Wallet | I24: 37 | J24: 427.62999999999994
A25: ORD100023 | B25: 44927.958 | C25: Bangalore | D25: Urban Tadka | E25: 656.55 | F25: 41.64 | G25: 420.57 | H25: Card | I25: 81 | J25: 277.61999999999995
A26: ORD100024 | B26: 44928 | C26: Chennai | D26: Pizza Corner | E26: 1239.17 | F26: 90.46 | G26: 90.59 | H26: Card | I26: 12 | J26: 1239.0400000000002
A27: ORD100025 | B27: 44928.042 | C27: Kolkata | D27: South Express | E27: 1898.75 | F27: 10.28 | G27: 371.4 | H27: UPI | I27: 26 | J27: 1537.63
A28: ORD100026 | B28: 44928.083 | C28: Pune | D28: Pizza Corner | E28: 1879.83 | F28: 34.22 | G28: 441.52 | H28: Cash | I28: 54 | J28: 1472.53
A29: ORD100027 | B29: 44928.125 | C29: Bangalore | D29: South Express | E29: 1358.03 | F29: 24.87 | G29: 300.22 | H29: Card | I29: 19 | J29: 1082.6799999999998
A30: ORD100028 | B30: 44928.167 | C30: Chennai | D30: Urban Tadka | E30: 931.37 | F30: 1.31 | G30: 368.09 | H30: Cash | I30: 55 | J30: 564.5899999999999
A31: ORD100029 | B31: 44928.208 | C31: Mumbai | D31: Pizza Corner | E31: 796.86 | F31: 38.64 | G31: 464.24 | H31: Wallet | I31: 15 | J31: 371.26
A32: ORD100030 | B32: 44928.25 | C32: Mumbai | D32: Urban Tadka | E32: 1861.19 | F32: 54.93 | G32: 153.03 | H32: Cash | I32: 37 | J32: 1763.0900000000001
A33: ORD100031 | B33: 44928.292 | C33: Pune | D33: Biryani House | E33: 916.22 | F33: 61.65 | G33: 246.7 | H33: Card | I33: 48 | J33: 731.1700000000001
A34: ORD100032 | B34: 44928.333 | C34: Delhi | D34: Spice Hub | E34: 1747.22 | F34: 32.86 | G34: 363.05 | H34: Cash | I34: 81 | J34: 1417.03
A35: ORD100033 | B35: 44928.375 | C35: Pune | D35: South Express | E35: 1741.44 | F35: 84.4 | G35: 17.32 | H35: Cash | I35: 87 | J35: 1808.5200000000002
A36: ORD100034 | B36: 44928.417 | C36: Kolkata | D36: Urban Tadka | E36: 691.22 | F36: 75.47 | G36: 239.04 | H36: Cash | I36: 15 | J36: 527.6500000000001
A37: ORD100035 | B37: 44928.458 | C37: Mumbai | D37: Urban Tadka | E37: 1796.48 | F37: 69.19 | G37: 407.96 | H37: Wallet | I37: 25 | J37: 1457.71
A38: ORD100036 | B38: 44928.5 | C38: Mumbai | D38: Tandoori Nights | E38: 1527.5 | F38: 57.69 | G38: 164.33 | H38: Wallet | I38: 37 | J38: 1420.8600000000001
A39: ORD100037 | B39: 44928.542 | C39: Kolkata | D39: Urban Tadka | E39: 915.17 | F39: 4.02 | G39: 112.28 | H39: Card | I39: 58 | J39: 806.91
A40: ORD100038 | B40: 44928.583 | C40: Pune | D40: Biryani House | E40: 1123.85 | F40: 0.21 | G40: 192.29 | H40: UPI | I40: 38 | J40: 931.77
...

Sheet Cleaned Data
A1: Order_ID | B1: Order_Time | C1: City | D1: Restaurant | E1: Order_Value | F1: Delivery_Fee | G1: Discount | H1: Payment_Mode | I1: Delivery_Time_Min | J1: Final_Amount_Old | K1: Final_Amount | L1: Year | M1: Month | N1: Hour | O1: Order_Size
A2: ORD100000 | B2: 44927 | C2: Kolkata | D2: Pizza Corner | E2: 1349.85 | F2: 21.28 | G2: 462.51 | H2: Card | I2: 45 | J2: 908.6199999999999 | K2: =Table1[[#This Row],[Order_Value]]+Table1[[#This Row],[Delivery_Fee]]-Table1[[#This Row],[Discount]] -> 908.62 | L2: =YEAR(Table1[[#This Row],[Order_Time]]) -> 2023 | M2: =TEXT(Table1[[#This Row],[Order_Time]],"MMM") -> Jan | N2: =HOUR(Table1[[#This Row],[Order_Time]]) -> 0 | O2: =IF(Table1[[#This Row],[Order_Value]]>1000,"High","Low") -> High
A3: ORD100001 | B3: 44927.042 | C3: Hyderabad | D3: South Express | E3: 528.88 | F3: 64.92 | G3: 233.45 | H3: Card | I3: 82 | J3: 360.34999999999997 | K3: =Table1[[#This Row],[Order_Value]]+Table1[[#This Row],[Delivery_Fee]]-Table1[[#This Row],[Discount]] -> 360.35 | L3: =YEAR(Table1[[#This Row],[Order_Time]]) -> 2023 | M3: =TEXT(Table1[[#This Row],[Order_Time]],"MMM") -> Jan | N3: =HOUR(Table1[[#This Row],[Order_Time]]) -> 1 | O3: =IF(Table1[[#This Row],[Order_Value]]>1000,"High","Low") -> Low
A4: ORD100002 | B4: 44927.083 | C4: Chennai | D4: Pizza Corner | E4: 1590.35 | F4: 93.1 | G4: 326.73 | H4: Wallet | I4: 15 | J4: 1356.7199999999998 | K4: =Table1[[#This Row],[Order_Value]]+Table1[[#This Row],[Delivery_Fee]]-Table1[[#This Row],[Discount]] -> 1356.72 | L4: =YEAR(Table1[[#This Row],[Order_Time]]) -> 2023 | M4: =TEXT(Table1[[#This Row],[Order_Time]],"MMM") -> Jan | N4: =HOUR(Table1[[#This Row],[Order_Time]]) -> 2 | O4: =IF(Table1[[#This Row],[Order_Value]]>1000,"High","Low") -> High
A5: ORD100003 | B5: 44927.125 | C5: Delhi | D5: South Express | E5: 1834.73 | F5: 72.82 | G5: 92.2 | H5: Card | I5: 57 | J5: 1815.35 | K5: =Table1[[#This Row],[Order_Value]]+Table1[[#This Row],[Delivery_Fee]]-Table1[[#This Row],[Discount]] -> 1815.35 | L5: =YEAR(Table1[[#This Row],[Order_Time]]) -> 2023 | M5: =TEXT(Table1[[#This Row],[Order_Time]],"MMM") -> Jan | N5: =HOUR(Table1[[#This Row],[Order_Time]]) -> 3 | O5: =IF(Table1[[#This Row],[Order_Value]]>1000,"High","Low") -> High
A6: ORD100004 | B6: 44927.167 | C6: Mumbai | D6: Urban Tadka | E6: 1374.42 | F6: 50.05 | G6: 394.49 | H6: Cash | I6: 55 | J6: 1029.98 | K6: =Table1[[#This Row],[Order_Value]]+Table1[[#This Row],[Delivery_Fee]]-Table1[[#This Row],[Discount]] -> 1029.98 | L6: =YEAR(Table1[[#This Row],[Order_Time]]) -> 2023 | M6: =TEXT(Table1[[#This Row],[Order_Time]],"MMM") -> Jan | N6: =HOUR(Table1[[#This Row],[Order_Time]]) -> 4 | O6: =IF(Table1[[#This Row],[Order_Value]]>1000,"High","Low") -> High
A7: ORD100005 | B7: 44927.208 | C7: Hyderabad | D7: Tandoori Nights | E7: 1935.57 | F7: 5.7 | G7: 365.14 | H7: Wallet | I7: 28 | J7: 1576.13 | K7: =Table1[[#This Row],[Order_Value]]+Table1[[#This Row],[Delivery_Fee]]-Table1[[#This Row],[Discount]] -> 1576.13 | L7: =YEAR(Table1[[#This Row],[Order_Time]]) -> 2023 | M7: =TEXT(Table1[[#This Row],[Order_Time]],"MMM") -> Jan | N7: =HOUR(Table1[[#This Row],[Order_Time]]) -> 5 | O7: =IF(Table1[[#This Row],[Order_Value]]>1000,"High","Low") -> High
A8: ORD100006 | B8: 44927.25 | C8: Kolkata | D8: Tandoori Nights | E8: 944.53 | F8: 0.76 | G8: 372.22 | H8: UPI | I8: 85 | J8: 573.0699999999999 | K8: =Table1[[#This Row],[Order_Value]]+Table1[[#This Row],[Delivery_Fee]]-Table1[[#This Row],[Discount]] -> 573.07 | L8: =YEAR(Table1[[#This Row],[Order_Time]]) -> 2023 | M8: =TEXT(Table1[[#This Row],[Order_Time]],"MMM") -> Jan | N8: =HOUR(Table1[[#This Row],[Order_Time]]) -> 6 | O8: =IF(Table1[[#This Row],[Order_Value]]>1000,"High","Low") -> Low
A9: ORD100007 | B9: 44927.292 | C9: Delhi | D9: Spice Hub | E9: 1208.05 | F9: 97.27 | G9: 137.99 | H9: UPI | I9: 48 | J9: 1167.33 | K9: =Table1[[#This Row],[Order_Value]]+Table1[[#This Row],[Delivery_Fee]]-Table1[[#This Row],[Discount]] -> 1167.33 | L9: =YEAR(Table1[[#This Row],[Order_Time]]) -> 2023 | M9: =TEXT(Table1[[#This Row],[Order_Time]],"MMM") -> Jan | N9: =HOUR(Table1[[#This Row],[Order_Time]]) -> 7 | O9: =IF(Table1[[#This Row],[Order_Value]]>1000,"High","Low") -> High
A10: ORD100008 | B10: 44927.333 | C10: Delhi | D10: Urban Tadka | E10: 572.48 | F10: 23.16 | G10: 177.53 | H10: UPI | I10: 76 | J10: 418.11 | K10: =Table1[[#This Row],[Order_Value]]+Table1[[#This Row],[Delivery_Fee]]-Table1[[#This Row],[Discount]] -> 418.11 | L10: =YEAR(Table1[[#This Row],[Order_Time]]) -> 2023 | M10: =TEXT(Table1[[#This Row],[Order_Time]],"MMM") -> Jan | N10: =HOUR(Table1[[#This Row],[Order_Time]]) -> 8 | O10: =IF(Table1[[#This Row],[Order_Value]]>1000,"High","Low") -> Low
A11: ORD100009 | B11: 44927.375 | C11: Mumbai | D11: Pizza Corner | E11: 551.64 | F11: 54.33 | G11: 308.42 | H11: UPI | I11: 13 | J11: 297.55 | K11: =Table1[[#This Row],[Order_Value]]+Table1[[#This Row],[Delivery_Fee]]-Table1[[#This Row],[Discount]] -> 297.55 | L11: =YEAR(Table1[[#This Row],[Order_Time]]) -> 2023 | M11: =TEXT(Table1[[#This Row],[Order_Time]],"MMM") -> Jan | N11: =HOUR(Table1[[#This Row],[Order_Time]]) -> 9 | O11: =IF(Table1[[#This Row],[Order_Value]]>1000,"High","Low") -> Low
A12: ORD100010 | B12: 44927.417 | C12: Chennai | D12: South Express | E12: 483.8 | F12: 64.17 | G12: 352.64 | H12: Card | I12: 72 | J12: 195.33000000000004 | K12: =Table1[[#This Row],[Order_Value]]+Table1[[#This Row],[Delivery_Fee]]-Table1[[#This Row],[Discount]] -> 195.33 | L12: =YEAR(Table1[[#This Row],[Order_Time]]) -> 2023 | M12: =TEXT(Table1[[#This Row],[Order_Time]],"MMM") -> Jan | N12: =HOUR(Table1[[#This Row],[Order_Time]]) -> 10 | O12: =IF(Table1[[#This Row],[Order_Value]]>1000,"High","Low") -> Low
A13: ORD100011 | B13: 44927.458 | C13: Kolkata | D13: Biryani House | E13: 1838.77 | F13: 21.35 | G13: 198.95 | H13: Cash | I13: 10 | J13: 1661.1699999999998 | K13: =Table1[[#This Row],[Order_Value]]+Table1[[#This Row],[Delivery_Fee]]-Table1[[#This Row],[Discount]] -> 1661.17 | L13: =YEAR(Table1[[#This Row],[Order_Time]]) -> 2023 | M13: =TEXT(Table1[[#This Row],[Order_Time]],"MMM") -> Jan | N13: =HOUR(Table1[[#This Row],[Order_Time]]) -> 11 | O13: =IF(Table1[[#This Row],[Order_Value]]>1000,"High","Low") -> High
A14: ORD100012 | B14: 44927.5 | C14: Chennai | D14: Pizza Corner | E14: 886.72 | F14: 12.85 | G14: 26.19 | H14: Cash | I14: 82 | J14: 873.38 | K14: =Table1[[#This Row],[Order_Value]]+Table1[[#This Row],[Delivery_Fee]]-Table1[[#This Row],[Discount]] -> 873.38 | L14: =YEAR(Table1[[#This Row],[Order_Time]]) -> 2023 | M14: =TEXT(Table1[[#This Row],[Order_Time]],"MMM") -> Jan | N14: =HOUR(Table1[[#This Row],[Order_Time]]) -> 12 | O14: =IF(Table1[[#This Row],[Order_Value]]>1000,"High","Low") -> Low
A15: ORD100013 | B15: 44927.542 | C15: Pune | D15: Urban Tadka | E15: 1043.69 | F15: 79.71 | G15: 356.89 | H15: Card | I15: 58 | J15: 766.5100000000001 | K15: =Table1[[#This Row],[Order_Value]]+Table1[[#This Row],[Delivery_Fee]]-Table1[[#This Row],[Discount]] -> 766.51 | L15: =YEAR(Table1[[#This Row],[Order_Time]]) -> 2023 | M15: =TEXT(Table1[[#This Row],[Order_Time]],"MMM") -> Jan | N15: =HOUR(Table1[[#This Row],[Order_Time]]) -> 13 | O15: =IF(Table1[[#This Row],[Order_Value]]>1000,"High","Low") -> High
A16: ORD100014 | B16: 44927.583 | C16: Mumbai | D16: Tandoori Nights | E16: 1920.18 | F16: 11.99 | G16: 68.19 | H16: UPI | I16: 45 | J16: 1863.98 | K16: =Table1[[#This Row],[Order_Value]]+Table1[[#This Row],[Delivery_Fee]]-Table1[[#This Row],[Discount]] -> 1863.98 | L16: =YEAR(Table1[[#This Row],[Order_Time]]) -> 2023 | M16: =TEXT(Table1[[#This Row],[Order_Time]],"MMM") -> Jan | N16: =HOUR(Table1[[#This Row],[Order_Time]]) -> 14 | O16: =IF(Table1[[#This Row],[Order_Value]]>1000,"High","Low") -> High
A17: ORD100015 | B17: 44927.625 | C17: Unknown | D17: Biryani House | E17: 404.41 | F17: 32.97 | G17: 118.16 | H17: UPI | I17: 79 | J17: 319.22 | K17: =Table1[[#This Row],[Order_Value]]+Table1[[#This Row],[Delivery_Fee]]-Table1[[#This Row],[Discount]] -> 319.22 | L17: =YEAR(Table1[[#This Row],[Order_Time]]) -> 2023 | M17: =TEXT(Table1[[#This Row],[Order_Time]],"MMM") -> Jan | N17: =HOUR(Table1[[#This Row],[Order_Time]]) -> 15 | O17: =IF(Table1[[#This Row],[Order_Value]]>1000,"High","Low") -> Low
A18: ORD100016 | B18: 44927.667 | C18: Chennai | D18: Pizza Corner | E18: 895.09 | F18: 21.67 | G18: 412.06 | H18: Wallet | I18: 10 | J18: 504.7 | K18: =Table1[[#This Row],[Order_Value]]+Table1[[#This Row],[Delivery_Fee]]-Table1[[#This Row],[Discount]] -> 504.7 | L18: =YEAR(Table1[[#This Row],[Order_Time]]) -> 2023 | M18: =TEXT(Table1[[#This Row],[Order_Time]],"MMM") -> Jan | N18: =HOUR(Table1[[#This Row],[Order_Time]]) -> 16 | O18: =IF(Table1[[#This Row],[Order_Value]]>1000,"High","Low") -> Low
A19: ORD100017 | B19: 44927.708 | C19: Pune | D19: Tandoori Nights | E19: 1861.77 | F19: 12.5 | G19: 29.64 | H19: Cash | I19: 73 | J19: 1844.6299999999999 | K19: =Table1[[#This Row],[Order_Value]]+Table1[[#This Row],[Delivery_Fee]]-Table1[[#This Row],[Discount]] -> 1844.63 | L19: =YEAR(Table1[[#This Row],[Order_Time]]) -> 2023 | M19: =TEXT(Table1[[#This Row],[Order_Time]],"MMM") -> Jan | N19: =HOUR(Table1[[#This Row],[Order_Time]]) -> 17 | O19: =IF(Table1[[#This Row],[Order_Value]]>1000,"High","Low") -> High
A20: ORD100018 | B20: 44927.75 | C20: Kolkata | D20: Spice Hub | E20: 1183.04 | F20: 71.24 | G20: 239.14 | H20: UPI | I20: 52 | J20: 1015.14 | K20: =Table1[[#This Row],[Order_Value]]+Table1[[#This Row],[Delivery_Fee]]-Table1[[#This Row],[Discount]] -> 1015.14 | L20: =YEAR(Table1[[#This Row],[Order_Time]]) -> 2023 | M20: =TEXT(Table1[[#This Row],[Order_Time]],"MMM") -> Jan | N20: =HOUR(Table1[[#This Row],[Order_Time]]) -> 18 | O20: =IF(Table1[[#This Row],[Order_Value]]>1000,"High","Low") -> High
A21: ORD100019 | B21: 44927.792 | C21: Bangalore | D21: Urban Tadka | E21: 827.72 | F21: 73.55 | G21: 59.43 | H21: Cash | I21: 38 | J21: 841.84 | K21: =Table1[[#This Row],[Order_Value]]+Table1[[#This Row],[Delivery_Fee]]-Table1[[#This Row],[Discount]] -> 841.84 | L21: =YEAR(Table1[[#This Row],[Order_Time]]) -> 2023 | M21: =TEXT(Table1[[#This Row],[Order_Time]],"MMM") -> Jan | N21: =HOUR(Table1[[#This Row],[Order_Time]]) -> 19 | O21: =IF(Table1[[#This Row],[Order_Value]]>1000,"High","Low") -> Low
A22: ORD100020 | B22: 44927.833 | C22: Chennai | D22: Tandoori Nights | E22: 1091.84 | F22: 82.62 | G22: 188.33 | H22: UPI | I22: 27 | J22: 986.13 | K22: =Table1[[#This Row],[Order_Value]]+Table1[[#This Row],[Delivery_Fee]]-Table1[[#This Row],[Discount]] -> 986.13 | L22: =YEAR(Table1[[#This Row],[Order_Time]]) -> 2023 | M22: =TEXT(Table1[[#This Row],[Order_Time]],"MMM") -> Jan | N22: =HOUR(Table1[[#This Row],[Order_Time]]) -> 20 | O22: =IF(Table1[[#This Row],[Order_Value]]>1000,"High","Low") -> High
A23: ORD100021 | B23: 44927.875 | C23: Hyderabad | D23: South Express | E23: 1972.65 | F23: 73.61 | G23: 335.02 | H23: UPI | I23: 40 | J23: 1711.24 | K23: =Table1[[#This Row],[Order_Value]]+Table1[[#This Row],[Delivery_Fee]]-Table1[[#This Row],[Discount]] -> 1711.24 | L23: =YEAR(Table1[[#This Row],[Order_Time]]) -> 2023 | M23: =TEXT(Table1[[#This Row],[Order_Time]],"MMM") -> Jan | N23: =HOUR(Table1[[#This Row],[Order_Time]]) -> 21 | O23: =IF(Table1[[#This Row],[Order_Value]]>1000,"High","Low") -> High
A24: ORD100022 | B24: 44927.917 | C24: Chennai | D24: South Express | E24: 650.05 | F24: 85.15 | G24: 307.57 | H24: Wallet | I24: 37 | J24: 427.62999999999994 | K24: =Table1[[#This Row],[Order_Value]]+Table1[[#This Row],[Delivery_Fee]]-Table1[[#This Row],[Discount]] -> 427.63 | L24: =YEAR(Table1[[#This Row],[Order_Time]]) -> 2023 | M24: =TEXT(Table1[[#This Row],[Order_Time]],"MMM") -> Jan | N24: =HOUR(Table1[[#This Row],[Order_Time]]) -> 22 | O24: =IF(Table1[[#This Row],[Order_Value]]>1000,"High","Low") -> Low
A25: ORD100023 | B25: 44927.958 | C25: Bangalore | D25: Urban Tadka | E25: 656.55 | F25: 41.64 | G25: 420.57 | H25: Card | I25: 81 | J25: 277.61999999999995 | K25: =Table1[[#This Row],[Order_Value]]+Table1[[#This Row],[Delivery_Fee]]-Table1[[#This Row],[Discount]] -> 277.62 | L25: =YEAR(Table1[[#This Row],[Order_Time]]) -> 2023 | M25: =TEXT(Table1[[#This Row],[Order_Time]],"MMM") -> Jan | N25: =HOUR(Table1[[#This Row],[Order_Time]]) -> 23 | O25: =IF(Table1[[#This Row],[Order_Value]]>1000,"High","Low") -> Low
A26: ORD100024 | B26: 44928 | C26: Chennai | D26: Pizza Corner | E26: 1239.17 | F26: 90.46 | G26: 90.59 | H26: Card | I26: 12 | J26: 1239.0400000000002 | K26: =Table1[[#This Row],[Order_Value]]+Table1[[#This Row],[Delivery_Fee]]-Table1[[#This Row],[Discount]] -> 1239.04 | L26: =YEAR(Table1[[#This Row],[Order_Time]]) -> 2023 | M26: =TEXT(Table1[[#This Row],[Order_Time]],"MMM") -> Jan | N26: =HOUR(Table1[[#This Row],[Order_Time]]) -> 0 | O26: =IF(Table1[[#This Row],[Order_Value]]>1000,"High","Low") -> High
A27: ORD100025 | B27: 44928.042 | C27: Kolkata | D27: South Express | E27: 1898.75 | F27: 10.28 | G27: 371.4 | H27: UPI | I27: 26 | J27: 1537.63 | K27: =Table1[[#This Row],[Order_Value]]+Table1[[#This Row],[Delivery_Fee]]-Table1[[#This Row],[Discount]] -> 1537.63 | L27: =YEAR(Table1[[#This Row],[Order_Time]]) -> 2023 | M27: =TEXT(Table1[[#This Row],[Order_Time]],"MMM") -> Jan | N27: =HOUR(Table1[[#This Row],[Order_Time]]) -> 1 | O27: =IF(Table1[[#This Row],[Order_Value]]>1000,"High","Low") -> High
A28: ORD100026 | B28: 44928.083 | C28: Pune | D28: Pizza Corner | E28: 1879.83 | F28: 34.22 | G28: 441.52 | H28: Cash | I28: 54 | J28: 1472.53 | K28: =Table1[[#This Row],[Order_Value]]+Table1[[#This Row],[Delivery_Fee]]-Table1[[#This Row],[Discount]] -> 1472.53 | L28: =YEAR(Table1[[#This Row],[Order_Time]]) -> 2023 | M28: =TEXT(Table1[[#This Row],[Order_Time]],"MMM") -> Jan | N28: =HOUR(Table1[[#This Row],[Order_Time]]) -> 2 | O28: =IF(Table1[[#This Row],[Order_Value]]>1000,"High","Low") -> High
A29: ORD100027 | B29: 44928.125 | C29: Bangalore | D29: South Express | E29: 1358.03 | F29: 24.87 | G29: 300.22 | H29: Card | I29: 19 | J29: 1082.6799999999998 | K29: =Table1[[#This Row],[Order_Value]]+Table1[[#This Row],[Delivery_Fee]]-Table1[[#This Row],[Discount]] -> 1082.68 | L29: =YEAR(Table1[[#This Row],[Order_Time]]) -> 2023 | M29: =TEXT(Table1[[#This Row],[Order_Time]],"MMM") -> Jan | N29: =HOUR(Table1[[#This Row],[Order_Time]]) -> 3 | O29: =IF(Table1[[#This Row],[Order_Value]]>1000,"High","Low") -> High
A30: ORD100028 | B30: 44928.167 | C30: Chennai | D30: Urban Tadka | E30: 931.37 | F30: 1.31 | G30: 368.09 | H30: Cash | I30: 55 | J30: 564.5899999999999 | K30: =Table1[[#This Row],[Order_Value]]+Table1[[#This Row],[Delivery_Fee]]-Table1[[#This Row],[Discount]] -> 564.59 | L30: =YEAR(Table1[[#This Row],[Order_Time]]) -> 2023 | M30: =TEXT(Table1[[#This Row],[Order_Time]],"MMM") -> Jan | N30: =HOUR(Table1[[#This Row],[Order_Time]]) -> 4 | O30: =IF(Table1[[#This Row],[Order_Value]]>1000,"High","Low") -> Low
A31: ORD100029 | B31: 44928.208 | C31: Mumbai | D31: Pizza Corner | E31: 796.86 | F31: 38.64 | G31: 464.24 | H31: Wallet | I31: 15 | J31: 371.26 | K31: =Table1[[#This Row],[Order_Value]]+Table1[[#This Row],[Delivery_Fee]]-Table1[[#This Row],[Discount]] -> 371.26 | L31: =YEAR(Table1[[#This Row],[Order_Time]]) -> 2023 | M31: =TEXT(Table1[[#This Row],[Order_Time]],"MMM") -> Jan | N31: =HOUR(Table1[[#This Row],[Order_Time]]) -> 5 | O31: =IF(Table1[[#This Row],[Order_Value]]>1000,"High","Low") -> Low
A32: ORD100030 | B32: 44928.25 | C32: Mumbai | D32: Urban Tadka | E32: 1861.19 | F32: 54.93 | G32: 153.03 | H32: Cash | I32: 37 | J32: 1763.0900000000001 | K32: =Table1[[#This Row],[Order_Value]]+Table1[[#This Row],[Delivery_Fee]]-Table1[[#This Row],[Discount]] -> 1763.09 | L32: =YEAR(Table1[[#This Row],[Order_Time]]) -> 2023 | M32: =TEXT(Table1[[#This Row],[Order_Time]],"MMM") -> Jan | N32: =HOUR(Table1[[#This Row],[Order_Time]]) -> 6 | O32: =IF(Table1[[#This Row],[Order_Value]]>1000,"High","Low") -> High
A33: ORD100031 | B33: 44928.292 | C33: Pune | D33: Biryani House | E33: 916.22 | F33: 61.65 | G33: 246.7 | H33: Card | I33: 48 | J33: 731.1700000000001 | K33: =Table1[[#This Row],[Order_Value]]+Table1[[#This Row],[Delivery_Fee]]-Table1[[#This Row],[Discount]] -> 731.17 | L33: =YEAR(Table1[[#This Row],[Order_Time]]) -> 2023 | M33: =TEXT(Table1[[#This Row],[Order_Time]],"MMM") -> Jan | N33: =HOUR(Table1[[#This Row],[Order_Time]]) -> 7 | O33: =IF(Table1[[#This Row],[Order_Value]]>1000,"High","Low") -> Low
A34: ORD100032 | B34: 44928.333 | C34: Delhi | D34: Spice Hub | E34: 1747.22 | F34: 32.86 | G34: 363.05 | H34: Cash | I34: 81 | J34: 1417.03 | K34: =Table1[[#This Row],[Order_Value]]+Table1[[#This Row],[Delivery_Fee]]-Table1[[#This Row],[Discount]] -> 1417.03 | L34: =YEAR(Table1[[#This Row],[Order_Time]]) -> 2023 | M34: =TEXT(Table1[[#This Row],[Order_Time]],"MMM") -> Jan | N34: =HOUR(Table1[[#This Row],[Order_Time]]) -> 8 | O34: =IF(Table1[[#This Row],[Order_Value]]>1000,"High","Low") -> High
A35: ORD100033 | B35: 44928.375 | C35: Pune | D35: South Express | E35: 1741.44 | F35: 84.4 | G35: 17.32 | H35: Cash | I35: 87 | J35: 1808.5200000000002 | K35: =Table1[[#This Row],[Order_Value]]+Table1[[#This Row],[Delivery_Fee]]-Table1[[#This Row],[Discount]] -> 1808.52 | L35: =YEAR(Table1[[#This Row],[Order_Time]]) -> 2023 | M35: =TEXT(Table1[[#This Row],[Order_Time]],"MMM") -> Jan | N35: =HOUR(Table1[[#This Row],[Order_Time]]) -> 9 | O35: =IF(Table1[[#This Row],[Order_Value]]>1000,"High","Low") -> High
A36: ORD100034 | B36: 44928.417 | C36: Kolkata | D36: Urban Tadka | E36: 691.22 | F36: 75.47 | G36: 239.04 | H36: Cash | I36: 15 | J36: 527.6500000000001 | K36: =Table1[[#This Row],[Order_Value]]+Table1[[#This Row],[Delivery_Fee]]-Table1[[#This Row],[Discount]] -> 527.65 | L36: =YEAR(Table1[[#This Row],[Order_Time]]) -> 2023 | M36: =TEXT(Table1[[#This Row],[Order_Time]],"MMM") -> Jan | N36: =HOUR(Table1[[#This Row],[Order_Time]]) -> 10 | O36: =IF(Table1[[#This Row],[Order_Value]]>1000,"High","Low") -> Low
A37: ORD100035 | B37: 44928.458 | C37: Mumbai | D37: Urban Tadka | E37: 1796.48 | F37: 69.19 | G37: 407.96 | H37: Wallet | I37: 25 | J37: 1457.71 | K37: =Table1[[#This Row],[Order_Value]]+Table1[[#This Row],[Delivery_Fee]]-Table1[[#This Row],[Discount]] -> 1457.71 | L37: =YEAR(Table1[[#This Row],[Order_Time]]) -> 2023 | M37: =TEXT(Table1[[#This Row],[Order_Time]],"MMM") -> Jan | N37: =HOUR(Table1[[#This Row],[Order_Time]]) -> 11 | O37: =IF(Table1[[#This Row],[Order_Value]]>1000,"High","Low") -> High
A38: ORD100036 | B38: 44928.5 | C38: Mumbai | D38: Tandoori Nights | E38: 1527.5 | F38: 57.69 | G38: 164.33 | H38: Wallet | I38: 37 | J38: 1420.8600000000001 | K38: =Table1[[#This Row],[Order_Value]]+Table1[[#This Row],[Delivery_Fee]]-Table1[[#This Row],[Discount]] -> 1420.86 | L38: =YEAR(Table1[[#This Row],[Order_Time]]) -> 2023 | M38: =TEXT(Table1[[#This Row],[Order_Time]],"MMM") -> Jan | N38: =HOUR(Table1[[#This Row],[Order_Time]]) -> 12 | O38: =IF(Table1[[#This Row],[Order_Value]]>1000,"High","Low") -> High
A39: ORD100037 | B39: 44928.542 | C39: Kolkata | D39: Urban Tadka | E39: 915.17 | F39: 4.02 | G39: 112.28 | H39: Card | I39: 58 | J39: 806.91 | K39: =Table1[[#This Row],[Order_Value]]+Table1[[#This Row],[Delivery_Fee]]-Table1[[#This Row],[Discount]] -> 806.91 | L39: =YEAR(Table1[[#This Row],[Order_Time]]) -> 2023 | M39: =TEXT(Table1[[#This Row],[Order_Time]],"MMM") -> Jan | N39: =HOUR(Table1[[#This Row],[Order_Time]]) -> 13 | O39: =IF(Table1[[#This Row],[Order_Value]]>1000,"High","Low") -> Low
A40: ORD100038 | B40: 44928.583 | C40: Pune | D40: Biryani House | E40: 1123.85 | F40: 0.21 | G40: 192.29 | H40: UPI | I40: 38 | J40: 931.77 | K40: =Table1[[#This Row],[Order_Value]]+Table1[[#This Row],[Delivery_Fee]]-Table1[[#This Row],[Discount]] -> 931.77 | L40: =YEAR(Table1[[#This Row],[Order_Time]]) -> 2023 | M40: =TEXT(Table1[[#This Row],[Order_Time]],"MMM") -> Jan | N40: =HOUR(Table1[[#This Row],[Order_Time]]) -> 14 | O40: =IF(Table1[[#This Row],[Order_Value]]>1000,"High","Low") -> High
...

Sheet KPI_Tracker
A1: KEY PERFORMANCE INDICATOR
A3: KPI Name | D3: Actual Value | G3: Unit
A4: Total Orders | D4: =COUNTA('Cleaned Data'!A:A)-1 -> 5200 | G4: Count
A5: Total Amount | D5: =SUM('Cleaned Data'!K2:K5201) -> 4323690 | G5: ₹
A6: Average Order Value | D6: =AVERAGE('Cleaned Data'!K2:K5201) -> 831.47885 | G6: ₹
A7: Total Discount Given | D7: =SUM('Cleaned Data'!G2:G5201) -> 1290229.4 | G7: ₹
A8: Average Delivery Time | D8: =AVERAGE('Cleaned Data'!I2:I5201) -> 49.416538 | G8: Days

Sheet Dashboard
A1: FOOD DELIVERY PERFORMANCE DASHBOARD
A3: Revenue | Orders | Average Delivery Time | Average Order Value
A4: =KPI_Tracker!D5 -> 4323690 | D4: =KPI_Tracker!D4 -> 5200 | F4: =KPI_Tracker!D8 -> 49.416538 | J4: =KPI_Tracker!D6 -> 831.47885

Sheet Pivot_Analysis
A3: Peak Hours | D3: City Performance | I3: Delivery Performance
A4: Hours | B4: Count | D4: City | E4: Revenue | F4: Orders | G4: Avg Delivery Time | I4: City | J4: Avg Delivery Time | K4: Orders
A5: 15 | B5: 217 | D5: Bangalore | E5: 618231.05 | F5: 755 | G5: 48.468874 | I5: Bangalore | J5: 48.468874 | K5: 755
A6: 0 | B6: 217 | D6: Chennai | E6: 571618.65 | F6: 698 | G6: 48.290831 | I6: Kolkata | J6: 50.090788 | K6: 749
A7: 9 | B7: 217 | D7: Delhi | E7: 636649.48 | F7: 724 | G7: 48.890884 | I7: Pune | J7: 49.218157 | K7: 738
A8: 1 | B8: 217 | D8: Hyderabad | E8: 588137.03 | F8: 725 | G8: 50.398621 | I8: Hyderabad | J8: 50.398621 | K8: 725
A9: 13 | B9: 217 | D9: Kolkata | E9: 609875.7 | F9: 749 | G9: 50.090788 | I9: Delhi | J9: 48.890884 | K9: 724
A10: 2 | B10: 217 | D10: Mumbai | E10: 616596.65 | F10: 707 | G10: 50.161245 | I10: Mumbai | J10: 50.161245 | K10: 707
A11: 8 | B11: 217 | D11: Pune | E11: 596036.39 | F11: 738 | G11: 49.218157 | I11: Chennai | J11: 48.290831 | K11: 698
A12: 3 | B12: 217 | D12: Unknown | E12: 86545.08 | F12: 104 | G12: 52.153846 | I12: Unknown | J12: 52.153846 | K12: 104
A13: 10 | B13: 217 | D13: Grand Total | E13: 4323690 | F13: 5200 | G13: 49.416538 | I13: Grand Total | J13: 49.416538 | K13: 5200
A14: 4 | B14: 217
A15: 12 | B15: 217 | D15: Payment Mode | I15: Order Value / Revenue Analysis
A16: 5 | B16: 217 | D16: Payment Mode | E16: Total Orders | F16: Revenue | I16: Order Category | J16: Orders | K16: Revenue | L16: Avg Discount
A17: 14 | B17: 217 | D17: Wallet | E17: 1332 | F17: 1113066 | I17: High | J17: 2690 | K17: 3514404.1 | L17: 248.11135
A18: 6 | B18: 217 | D18: Cash | E18: 1316 | F18: 1089600.7 | I18: Low | J18: 2510 | K18: 809285.92 | L18: 248.13142
A19: 7 | B19: 217 | D19: UPI | E19: 1277 | F19: 1064231 | I19: Grand Total | J19: 5200 | K19: 4323690 | L19: 248.12104
A20: 11 | B20: 217 | D20: Card | E20: 1275 | F20: 1056792.3
A21: 23 | B21: 216 | D21: Grand Total | E21: 5200 | F21: 4323690
A22: 21 | B22: 216
A23: 20 | B23: 216 | D23: City Revenue | G23: Payment Mode
A24: 17 | B24: 216 | D24: City | E24: Revenue | G24: Payment Mode | H24: Total Orders
A25: 22 | B25: 216 | D25: Bangalore | E25: 618231.05 | G25: Wallet | H25: 1332
A26: 18 | B26: 216 | D26: Chennai | E26: 571618.65 | G26: Cash | H26: 1316
A27: 16 | B27: 216 | D27: Delhi | E27: 636649.48 | G27: UPI | H27: 1277
A28: 19 | B28: 216 | D28: Hyderabad | E28: 588137.03 | G28: Card | H28: 1275
A29: Grand Total | B29: 5200 | D29: Kolkata | E29: 609875.7 | G29: Grand Total | H29: 5200
D30: Mumbai | E30: 616596.65
D31: Pune | E31: 596036.39 | G31: Delivery Performance
D32: Unknown | E32: 86545.08 | G32: City | H32: Avg Delivery Time
D33: Grand Total | E33: 4323690 | G33: Bangalore | H33: 48.468874
G34: Chennai | H34: 48.290831
G35: Delhi | H35: 48.890884
G36: Hyderabad | H36: 50.398621
G37: Kolkata | H37: 50.090788
G38: Mumbai | H38: 50.161245
G39: Pune | H39: 49.218157
G40: Unknown | H40: 52.153846
G41: Grand Total | H41: 49.416538
